<?xml version="1.0"?>
<robot name="ev_rwd" xmlns:xacro="http://ros.org/wiki/xacro">
  <!-- Base link (chassis) -->
  <link name="chassis">
    <inertial>
      <origin xyz="0 0 0.1"/>
      <mass value="250.0"/> <!-- Adjust mass value as needed -->
      <inertia ixx="10.0" ixy="0.0" ixz="0.0" iyy="20.0" iyz="0.0" izz="30.0"/>
    </inertial>
    <visual>
      <geometry>
        <box size="1.5 0.6 0.2"/>
      </geometry>
      <material name="blue">
        <color rgba="0.0 0.0 1.0 1.0"/>
      </material>
    </visual>
    <collision>
      <geometry>
        <box size="1.5 0.6 0.2"/>
      </geometry>
    </collision>
  </link>

  <!-- Define the rear wheels -->
  <link name="rear_left_wheel">
    <visual>
      <geometry>
        <cylinder radius="0.15" length="0.1"/>
      </geometry>
      <material name="black"/>
    </visual>
    <collision>
      <geometry>
        <cylinder radius="0.15" length="0.1"/>
      </geometry>
    </collision>
  </link>

  <link name="rear_right_wheel">
    <visual>
      <geometry>
        <cylinder radius="0.15" length="0.1"/>
      </geometry>
      <material name="black"/>
    </visual>
    <collision>
      <geometry>
        <cylinder radius="0.15" length="0.1"/>
      </geometry>
    </collision>
  </link>

  <!-- Rear wheel joints -->
  <joint name="rear_left_wheel_joint" type="continuous">
    <parent link="chassis"/>
    <child link="rear_left_wheel"/>
    <origin xyz="0.7 0.3 0.05" rpy="0 0 0"/>
    <axis xyz="0 1 0"/>
  </joint>

  <joint name="rear_right_wheel_joint" type="continuous">
    <parent link="chassis"/>
    <child link="rear_right_wheel"/>
    <origin xyz="0.7 -0.3 0.05" rpy="0 0 0"/>
    <axis xyz="0 1 0"/>
  </joint>

  <!-- Add front wheels and joints similarly (steerable) -->
</robot>

